Traceback (most recent call last):
  File "/usr/lib/python3/dist-packages/urllib3/connection.py", line 169, in _new_conn
    conn = connection.create_connection(
  File "/usr/lib/python3/dist-packages/urllib3/util/connection.py", line 73, in create_connection
    for res in socket.getaddrinfo(host, port, family, socket.SOCK_STREAM):
  File "/usr/lib/python3.9/socket.py", line 953, in getaddrinfo
    for res in _socket.getaddrinfo(host, port, family, type, proto, flags):
socket.gaierror: [Errno -3] Temporary failure in name resolution

During handling of the above exception, another exception occurred:

Traceback (most recent call last):
  File "/home/pi/mainUnit.py", line 112, in <module>
    write_api.write(bucket, org, data) 
  File "/home/pi/.local/lib/python3.9/site-packages/influxdb_client/client/write_api.py", line 371, in write
    results = list(map(write_payload, payloads.items()))
  File "/home/pi/.local/lib/python3.9/site-packages/influxdb_client/client/write_api.py", line 369, in write_payload
    return self._post_write(_async_req, bucket, org, final_string, payload[0])
  File "/home/pi/.local/lib/python3.9/site-packages/influxdb_client/client/write_api.py", line 517, in _post_write
    return self._write_service.post_write(org=org, bucket=bucket, body=body, precision=precision,
  File "/home/pi/.local/lib/python3.9/site-packages/influxdb_client/service/write_service.py", line 63, in post_write
    (data) = self.post_write_with_http_info(org, bucket, body, **kwargs)  # noqa: E501
  File "/home/pi/.local/lib/python3.9/site-packages/influxdb_client/service/write_service.py", line 168, in post_write_with_http_info
    return self.api_client.call_api(
  File "/home/pi/.local/lib/python3.9/site-packages/influxdb_client/api_client.py", line 341, in call_api
    return self.__call_api(resource_path, method,
  File "/home/pi/.local/lib/python3.9/site-packages/influxdb_client/api_client.py", line 171, in __call_api
    response_data = self.request(
  File "/home/pi/.local/lib/python3.9/site-packages/influxdb_client/api_client.py", line 386, in request
    return self.rest_client.POST(url,
  File "/home/pi/.local/lib/python3.9/site-packages/influxdb_client/rest.py", line 304, in POST
    return self.request("POST", url,
  File "/home/pi/.local/lib/python3.9/site-packages/influxdb_client/rest.py", line 217, in request
    r = self.pool_manager.request(
  File "/usr/lib/python3/dist-packages/urllib3/request.py", line 78, in request
    return self.request_encode_body(
  File "/usr/lib/python3/dist-packages/urllib3/request.py", line 170, in request_encode_body
    return self.urlopen(method, url, **extra_kw)
  File "/usr/lib/python3/dist-packages/urllib3/poolmanager.py", line 375, in urlopen
    response = conn.urlopen(method, u.request_uri, **kw)
  File "/usr/lib/python3/dist-packages/urllib3/connectionpool.py", line 755, in urlopen
    retries = retries.increment(
  File "/usr/lib/python3/dist-packages/urllib3/util/retry.py", line 507, in increment
    raise six.reraise(type(error), error, _stacktrace)
  File "/usr/lib/python3/dist-packages/six.py", line 719, in reraise
    raise value
  File "/usr/lib/python3/dist-packages/urllib3/connectionpool.py", line 699, in urlopen
    httplib_response = self._make_request(
  File "/usr/lib/python3/dist-packages/urllib3/connectionpool.py", line 382, in _make_request
    self._validate_conn(conn)
  File "/usr/lib/python3/dist-packages/urllib3/connectionpool.py", line 1012, in _validate_conn
    conn.connect()
  File "/usr/lib/python3/dist-packages/urllib3/connection.py", line 353, in connect
    conn = self._new_conn()
  File "/usr/lib/python3/dist-packages/urllib3/connection.py", line 181, in _new_conn
    raise NewConnectionError(
urllib3.exceptions.NewConnectionError: <urllib3.connection.HTTPSConnection object at 0xb3129d90>: Failed to establish a new connection: [Errno -3] Temporary failure in name resolution
